/root/pj_crawling/venv/lib64/python3.4/site-packages/psycopg2/__init__.py:144: UserWarning: The psycopg2 wheel package will be renamed from release 2.8; in order to keep installing from binary please use "pip install psycopg2-binary" instead. For details see: <http://initd.org/psycopg/docs/install.html#binary-install-from-pypi>.
  """)
[02/Sep/2018 18:19:22] "GET / HTTP/1.1" 200 1716
[02/Sep/2018 18:19:25] "GET / HTTP/1.1" 200 1716
[02/Sep/2018 18:19:43] "GET / HTTP/1.1" 200 1716
Performing system checks...

System check identified no issues (0 silenced).
September 02, 2018 - 18:18:46
Django version 1.11.15, using settings 'crawl.settings'
Starting development server at http://0.0.0.0:8000/
Quit the server with CONTROL-C.
/root/pj_crawling/venv/lib64/python3.4/site-packages/psycopg2/__init__.py:144: UserWarning: The psycopg2 wheel package will be renamed from release 2.8; in order to keep installing from binary please use "pip install psycopg2-binary" instead. For details see: <http://initd.org/psycopg/docs/install.html#binary-install-from-pypi>.
  """)
Unhandled exception in thread started by <function check_errors.<locals>.wrapper at 0x7f4ef28de400>
Traceback (most recent call last):
  File "/root/pj_crawling/venv/lib64/python3.4/site-packages/django/utils/autoreload.py", line 228, in wrapper
    fn(*args, **kwargs)
  File "/root/pj_crawling/venv/lib64/python3.4/site-packages/django/core/management/commands/runserver.py", line 124, in inner_run
    self.check(display_num_errors=True)
  File "/root/pj_crawling/venv/lib64/python3.4/site-packages/django/core/management/base.py", line 359, in check
    include_deployment_checks=include_deployment_checks,
  File "/root/pj_crawling/venv/lib64/python3.4/site-packages/django/core/management/base.py", line 346, in _run_checks
    return checks.run_checks(**kwargs)
  File "/root/pj_crawling/venv/lib64/python3.4/site-packages/django/core/checks/registry.py", line 81, in run_checks
    new_errors = check(app_configs=app_configs)
  File "/root/pj_crawling/venv/lib64/python3.4/site-packages/django/core/checks/urls.py", line 16, in check_url_config
    return check_resolver(resolver)
  File "/root/pj_crawling/venv/lib64/python3.4/site-packages/django/core/checks/urls.py", line 26, in check_resolver
    return check_method()
  File "/root/pj_crawling/venv/lib64/python3.4/site-packages/django/urls/resolvers.py", line 256, in check
    for pattern in self.url_patterns:
  File "/root/pj_crawling/venv/lib64/python3.4/site-packages/django/utils/functional.py", line 35, in __get__
    res = instance.__dict__[self.name] = self.func(instance)
  File "/root/pj_crawling/venv/lib64/python3.4/site-packages/django/urls/resolvers.py", line 407, in url_patterns
    patterns = getattr(self.urlconf_module, "urlpatterns", self.urlconf_module)
  File "/root/pj_crawling/venv/lib64/python3.4/site-packages/django/utils/functional.py", line 35, in __get__
    res = instance.__dict__[self.name] = self.func(instance)
  File "/root/pj_crawling/venv/lib64/python3.4/site-packages/django/urls/resolvers.py", line 400, in urlconf_module
    return import_module(self.urlconf_name)
  File "/usr/lib64/python3.4/importlib/__init__.py", line 109, in import_module
    return _bootstrap._gcd_import(name[level:], package, level)
  File "<frozen importlib._bootstrap>", line 2254, in _gcd_import
  File "<frozen importlib._bootstrap>", line 2237, in _find_and_load
  File "<frozen importlib._bootstrap>", line 2226, in _find_and_load_unlocked
  File "<frozen importlib._bootstrap>", line 1200, in _load_unlocked
  File "<frozen importlib._bootstrap>", line 1129, in _exec
  File "<frozen importlib._bootstrap>", line 1471, in exec_module
  File "<frozen importlib._bootstrap>", line 321, in _call_with_frames_removed
  File "/root/pj_crawling/crawl/urls.py", line 21, in <module>
    url(r'', include('main_app.urls')),
  File "/root/pj_crawling/venv/lib64/python3.4/site-packages/django/conf/urls/__init__.py", line 50, in include
    urlconf_module = import_module(urlconf_module)
  File "/usr/lib64/python3.4/importlib/__init__.py", line 109, in import_module
    return _bootstrap._gcd_import(name[level:], package, level)
  File "<frozen importlib._bootstrap>", line 2254, in _gcd_import
  File "<frozen importlib._bootstrap>", line 2237, in _find_and_load
  File "<frozen importlib._bootstrap>", line 2224, in _find_and_load_unlocked
ImportError: No module named 'main_app.urls'
Performing system checks...

/root/pj_crawling/venv/lib64/python3.4/site-packages/psycopg2/__init__.py:144: UserWarning: The psycopg2 wheel package will be renamed from release 2.8; in order to keep installing from binary please use "pip install psycopg2-binary" instead. For details see: <http://initd.org/psycopg/docs/install.html#binary-install-from-pypi>.
  """)
Unhandled exception in thread started by <function check_errors.<locals>.wrapper at 0x7f834f5896a8>
Traceback (most recent call last):
  File "/root/pj_crawling/venv/lib64/python3.4/site-packages/django/utils/autoreload.py", line 228, in wrapper
    fn(*args, **kwargs)
  File "/root/pj_crawling/venv/lib64/python3.4/site-packages/django/core/management/commands/runserver.py", line 116, in inner_run
    autoreload.raise_last_exception()
  File "/root/pj_crawling/venv/lib64/python3.4/site-packages/django/utils/autoreload.py", line 251, in raise_last_exception
    six.reraise(*_exception)
  File "/root/pj_crawling/venv/lib64/python3.4/site-packages/django/utils/six.py", line 685, in reraise
    raise value.with_traceback(tb)
  File "/root/pj_crawling/venv/lib64/python3.4/site-packages/django/utils/autoreload.py", line 228, in wrapper
    fn(*args, **kwargs)
  File "/root/pj_crawling/venv/lib64/python3.4/site-packages/django/__init__.py", line 27, in setup
    apps.populate(settings.INSTALLED_APPS)
  File "/root/pj_crawling/venv/lib64/python3.4/site-packages/django/apps/registry.py", line 108, in populate
    app_config.import_models()
  File "/root/pj_crawling/venv/lib64/python3.4/site-packages/django/apps/config.py", line 202, in import_models
    self.models_module = import_module(models_module_name)
  File "/usr/lib64/python3.4/importlib/__init__.py", line 109, in import_module
    return _bootstrap._gcd_import(name[level:], package, level)
  File "<frozen importlib._bootstrap>", line 2254, in _gcd_import
  File "<frozen importlib._bootstrap>", line 2237, in _find_and_load
  File "<frozen importlib._bootstrap>", line 2226, in _find_and_load_unlocked
  File "<frozen importlib._bootstrap>", line 1200, in _load_unlocked
  File "<frozen importlib._bootstrap>", line 1129, in _exec
  File "<frozen importlib._bootstrap>", line 1467, in exec_module
  File "<frozen importlib._bootstrap>", line 1572, in get_code
  File "<frozen importlib._bootstrap>", line 1532, in source_to_code
  File "<frozen importlib._bootstrap>", line 321, in _call_with_frames_removed
  File "/root/pj_crawling/main_app/models.py", line 15
    return self.title
                    ^
TabError: inconsistent use of tabs and spaces in indentation
